[2024-07-09T05:48:00.704+0000] {local_task_job_runner.py:120} INFO - ::group::Pre task execution logs
[2024-07-09T05:48:00.727+0000] {taskinstance.py:2076} INFO - Dependencies all met for dep_context=non-requeueable deps ti=<TaskInstance: Email_test_dag.fail_task scheduled__2024-07-09T05:47:00+00:00 [queued]>
[2024-07-09T05:48:00.731+0000] {taskinstance.py:2076} INFO - Dependencies all met for dep_context=requeueable deps ti=<TaskInstance: Email_test_dag.fail_task scheduled__2024-07-09T05:47:00+00:00 [queued]>
[2024-07-09T05:48:00.732+0000] {taskinstance.py:2306} INFO - Starting attempt 1 of 2
[2024-07-09T05:48:00.739+0000] {taskinstance.py:2330} INFO - Executing <Task(BashOperator): fail_task> on 2024-07-09 05:47:00+00:00
[2024-07-09T05:48:00.749+0000] {logging_mixin.py:188} WARNING - /home/***/.local/lib/python3.12/site-packages/***/task/task_runner/standard_task_runner.py:61 DeprecationWarning: This process (pid=20491) is multi-threaded, use of fork() may lead to deadlocks in the child.
[2024-07-09T05:48:00.747+0000] {standard_task_runner.py:90} INFO - Running: ['***', 'tasks', 'run', 'Email_test_dag', 'fail_task', 'scheduled__2024-07-09T05:47:00+00:00', '--job-id', '2629', '--raw', '--subdir', 'DAGS_FOLDER/test_dag.py', '--cfg-path', '/tmp/tmp96fgqvc3']
[2024-07-09T05:48:00.750+0000] {standard_task_runner.py:63} INFO - Started process 20492 to run task
[2024-07-09T05:48:00.751+0000] {standard_task_runner.py:91} INFO - Job 2629: Subtask fail_task
[2024-07-09T05:48:00.821+0000] {task_command.py:426} INFO - Running <TaskInstance: Email_test_dag.fail_task scheduled__2024-07-09T05:47:00+00:00 [running]> on host ec4fc0d2456a
[2024-07-09T05:48:00.877+0000] {taskinstance.py:2648} INFO - Exporting env vars: AIRFLOW_CTX_DAG_EMAIL='thanh.huynh@onpoint.vn,congminh.nguyen@onpoint.vn' AIRFLOW_CTX_DAG_OWNER='thanh.huynh@onpoint.vn' AIRFLOW_CTX_DAG_ID='Email_test_dag' AIRFLOW_CTX_TASK_ID='fail_task' AIRFLOW_CTX_EXECUTION_DATE='2024-07-09T05:47:00+00:00' AIRFLOW_CTX_TRY_NUMBER='1' AIRFLOW_CTX_DAG_RUN_ID='scheduled__2024-07-09T05:47:00+00:00'
[2024-07-09T05:48:00.878+0000] {taskinstance.py:430} INFO - ::endgroup::
[2024-07-09T05:48:00.887+0000] {subprocess.py:63} INFO - Tmp dir root location: /tmp
[2024-07-09T05:48:00.888+0000] {subprocess.py:75} INFO - Running command: ['/usr/bin/bash', '-c', 'cd non_exist_folder']
[2024-07-09T05:48:00.893+0000] {subprocess.py:86} INFO - Output:
[2024-07-09T05:48:00.896+0000] {subprocess.py:93} INFO - /usr/bin/bash: line 1: cd: non_exist_folder: No such file or directory
[2024-07-09T05:48:00.896+0000] {subprocess.py:97} INFO - Command exited with return code 1
[2024-07-09T05:48:00.897+0000] {taskinstance.py:441} INFO - ::group::Post task execution logs
[2024-07-09T05:48:00.904+0000] {taskinstance.py:2905} ERROR - Task failed with exception
Traceback (most recent call last):
  File "/home/airflow/.local/lib/python3.12/site-packages/airflow/models/taskinstance.py", line 465, in _execute_task
    result = _execute_callable(context=context, **execute_callable_kwargs)
             ^^^^^^^^^^^^^^^^^^^^^^^^^^^^^^^^^^^^^^^^^^^^^^^^^^^^^^^^^^^^^
  File "/home/airflow/.local/lib/python3.12/site-packages/airflow/models/taskinstance.py", line 432, in _execute_callable
    return execute_callable(context=context, **execute_callable_kwargs)
           ^^^^^^^^^^^^^^^^^^^^^^^^^^^^^^^^^^^^^^^^^^^^^^^^^^^^^^^^^^^^
  File "/home/airflow/.local/lib/python3.12/site-packages/airflow/models/baseoperator.py", line 401, in wrapper
    return func(self, *args, **kwargs)
           ^^^^^^^^^^^^^^^^^^^^^^^^^^^
  File "/home/airflow/.local/lib/python3.12/site-packages/airflow/operators/bash.py", line 243, in execute
    raise AirflowException(
airflow.exceptions.AirflowException: Bash command failed. The command returned a non-zero exit code 1.
[2024-07-09T05:48:00.907+0000] {taskinstance.py:1206} INFO - Marking task as UP_FOR_RETRY. dag_id=Email_test_dag, task_id=fail_task, run_id=scheduled__2024-07-09T05:47:00+00:00, execution_date=20240709T054700, start_date=20240709T054800, end_date=20240709T054800
[2024-07-09T05:48:00.933+0000] {logging_mixin.py:188} WARNING - /home/***/.local/lib/python3.12/site-packages/***/utils/email.py:154 RemovedInAirflow3Warning: Fetching SMTP credentials from configuration variables will be deprecated in a future release. Please set credentials using a connection instead.
[2024-07-09T05:48:00.934+0000] {email.py:271} INFO - Email alerting: attempt 1
[2024-07-09T05:48:07.284+0000] {email.py:271} INFO - Email alerting: attempt 1
[2024-07-09T05:48:13.739+0000] {taskinstance.py:879} ERROR - Failed to send email to: ['thanh.huynh@onpoint.vn', 'congminh.nguyen@onpoint.vn']
Traceback (most recent call last):
  File "/home/airflow/.local/lib/python3.12/site-packages/airflow/models/taskinstance.py", line 2479, in _run_raw_task
    self._execute_task_with_callbacks(context, test_mode, session=session)
  File "/home/airflow/.local/lib/python3.12/site-packages/airflow/models/taskinstance.py", line 2676, in _execute_task_with_callbacks
    result = self._execute_task(context, task_orig)
             ^^^^^^^^^^^^^^^^^^^^^^^^^^^^^^^^^^^^^^
  File "/home/airflow/.local/lib/python3.12/site-packages/airflow/models/taskinstance.py", line 2701, in _execute_task
    return _execute_task(self, context, task_orig)
           ^^^^^^^^^^^^^^^^^^^^^^^^^^^^^^^^^^^^^^^
  File "/home/airflow/.local/lib/python3.12/site-packages/airflow/models/taskinstance.py", line 465, in _execute_task
    result = _execute_callable(context=context, **execute_callable_kwargs)
             ^^^^^^^^^^^^^^^^^^^^^^^^^^^^^^^^^^^^^^^^^^^^^^^^^^^^^^^^^^^^^
  File "/home/airflow/.local/lib/python3.12/site-packages/airflow/models/taskinstance.py", line 432, in _execute_callable
    return execute_callable(context=context, **execute_callable_kwargs)
           ^^^^^^^^^^^^^^^^^^^^^^^^^^^^^^^^^^^^^^^^^^^^^^^^^^^^^^^^^^^^
  File "/home/airflow/.local/lib/python3.12/site-packages/airflow/models/baseoperator.py", line 401, in wrapper
    return func(self, *args, **kwargs)
           ^^^^^^^^^^^^^^^^^^^^^^^^^^^
  File "/home/airflow/.local/lib/python3.12/site-packages/airflow/operators/bash.py", line 243, in execute
    raise AirflowException(
airflow.exceptions.AirflowException: Bash command failed. The command returned a non-zero exit code 1.

During handling of the above exception, another exception occurred:

Traceback (most recent call last):
  File "/home/airflow/.local/lib/python3.12/site-packages/airflow/models/taskinstance.py", line 1063, in _email_alert
    send_email(task.email, subject, html_content)
  File "/home/airflow/.local/lib/python3.12/site-packages/airflow/utils/email.py", line 80, in send_email
    return backend(
           ^^^^^^^^
  File "/home/airflow/.local/lib/python3.12/site-packages/airflow/utils/email.py", line 154, in send_email_smtp
    send_mime_email(e_from=mail_from, e_to=recipients, mime_msg=msg, conn_id=conn_id, dryrun=dryrun)
  File "/home/airflow/.local/lib/python3.12/site-packages/airflow/utils/email.py", line 281, in send_mime_email
    smtp_conn.login(smtp_user, smtp_password)
  File "/usr/local/lib/python3.12/smtplib.py", line 750, in login
    raise last_exception
  File "/usr/local/lib/python3.12/smtplib.py", line 739, in login
    (code, resp) = self.auth(
                   ^^^^^^^^^^
  File "/usr/local/lib/python3.12/smtplib.py", line 662, in auth
    raise SMTPAuthenticationError(code, resp)
smtplib.SMTPAuthenticationError: (535, b'5.7.139 Authentication unsuccessful, SmtpClientAuthentication is disabled for the Tenant. Visit https://aka.ms/smtp_auth_disabled for more information. [JH0PR02CA0001.apcprd02.prod.outlook.com 2024-07-09T05:48:07.310Z 08DC9F6BC5939DB5]')

During handling of the above exception, another exception occurred:

Traceback (most recent call last):
  File "/home/airflow/.local/lib/python3.12/site-packages/airflow/models/taskinstance.py", line 877, in _handle_failure
    task_instance.email_alert(error, failure_context["task"])
  File "/home/airflow/.local/lib/python3.12/site-packages/airflow/models/taskinstance.py", line 3163, in email_alert
    _email_alert(task_instance=self, exception=exception, task=task)
  File "/home/airflow/.local/lib/python3.12/site-packages/airflow/models/taskinstance.py", line 1065, in _email_alert
    send_email(task.email, subject, html_content_err)
  File "/home/airflow/.local/lib/python3.12/site-packages/airflow/utils/email.py", line 80, in send_email
    return backend(
           ^^^^^^^^
  File "/home/airflow/.local/lib/python3.12/site-packages/airflow/utils/email.py", line 154, in send_email_smtp
    send_mime_email(e_from=mail_from, e_to=recipients, mime_msg=msg, conn_id=conn_id, dryrun=dryrun)
  File "/home/airflow/.local/lib/python3.12/site-packages/airflow/utils/email.py", line 281, in send_mime_email
    smtp_conn.login(smtp_user, smtp_password)
  File "/usr/local/lib/python3.12/smtplib.py", line 750, in login
    raise last_exception
  File "/usr/local/lib/python3.12/smtplib.py", line 739, in login
    (code, resp) = self.auth(
                   ^^^^^^^^^^
  File "/usr/local/lib/python3.12/smtplib.py", line 662, in auth
    raise SMTPAuthenticationError(code, resp)
smtplib.SMTPAuthenticationError: (535, b'5.7.139 Authentication unsuccessful, SmtpClientAuthentication is disabled for the Tenant. Visit https://aka.ms/smtp_auth_disabled for more information. [SG2P153CA0030.APCP153.PROD.OUTLOOK.COM 2024-07-09T05:48:13.792Z 08DC9C627B32F54E]')
[2024-07-09T05:48:13.783+0000] {standard_task_runner.py:110} ERROR - Failed to execute job 2629 for task fail_task (Bash command failed. The command returned a non-zero exit code 1.; 20492)
[2024-07-09T05:48:13.809+0000] {local_task_job_runner.py:240} INFO - Task exited with return code 1
[2024-07-09T05:48:13.835+0000] {taskinstance.py:3503} INFO - 0 downstream tasks scheduled from follow-on schedule check
[2024-07-09T05:48:13.836+0000] {local_task_job_runner.py:222} INFO - ::endgroup::
