[2024-07-10T23:22:54.740+0000] {local_task_job_runner.py:120} INFO - ::group::Pre task execution logs
[2024-07-10T23:22:54.756+0000] {taskinstance.py:2076} INFO - Dependencies all met for dep_context=non-requeueable deps ti=<TaskInstance: Fail_Dags_Monitor.load scheduled__2024-07-10T21:15:00+00:00 [queued]>
[2024-07-10T23:22:54.760+0000] {taskinstance.py:2076} INFO - Dependencies all met for dep_context=requeueable deps ti=<TaskInstance: Fail_Dags_Monitor.load scheduled__2024-07-10T21:15:00+00:00 [queued]>
[2024-07-10T23:22:54.760+0000] {taskinstance.py:2306} INFO - Starting attempt 2 of 3
[2024-07-10T23:22:54.766+0000] {taskinstance.py:2330} INFO - Executing <Task(PythonOperator): load> on 2024-07-10 21:15:00+00:00
[2024-07-10T23:22:54.771+0000] {logging_mixin.py:188} WARNING - /home/***/.local/lib/python3.12/site-packages/***/task/task_runner/standard_task_runner.py:61 DeprecationWarning: This process (pid=2156) is multi-threaded, use of fork() may lead to deadlocks in the child.
[2024-07-10T23:22:54.771+0000] {standard_task_runner.py:90} INFO - Running: ['***', 'tasks', 'run', 'Fail_Dags_Monitor', 'load', 'scheduled__2024-07-10T21:15:00+00:00', '--job-id', '168', '--raw', '--subdir', 'DAGS_FOLDER/fail_dags_monitor.py', '--cfg-path', '/tmp/tmp3g0_cmfk']
[2024-07-10T23:22:54.772+0000] {standard_task_runner.py:63} INFO - Started process 2161 to run task
[2024-07-10T23:22:54.773+0000] {standard_task_runner.py:91} INFO - Job 168: Subtask load
[2024-07-10T23:22:54.797+0000] {task_command.py:426} INFO - Running <TaskInstance: Fail_Dags_Monitor.load scheduled__2024-07-10T21:15:00+00:00 [running]> on host 469b2f9527f6
[2024-07-10T23:22:54.841+0000] {taskinstance.py:2648} INFO - Exporting env vars: AIRFLOW_CTX_DAG_OWNER='congminh.nguyen@onpoint.vn' AIRFLOW_CTX_DAG_ID='Fail_Dags_Monitor' AIRFLOW_CTX_TASK_ID='load' AIRFLOW_CTX_EXECUTION_DATE='2024-07-10T21:15:00+00:00' AIRFLOW_CTX_TRY_NUMBER='2' AIRFLOW_CTX_DAG_RUN_ID='scheduled__2024-07-10T21:15:00+00:00'
[2024-07-10T23:22:54.842+0000] {taskinstance.py:430} INFO - ::endgroup::
[2024-07-10T23:22:54.947+0000] {dagbag.py:545} INFO - Filling up the DagBag from /opt/***/dags
[2024-07-11T00:32:33.419+0000] {local_task_job_runner.py:288} WARNING - Recorded pid 2210 does not match the current pid 2161
[2024-07-11T00:32:33.421+0000] {local_task_job_runner.py:222} INFO - ::endgroup::
[2024-07-11T00:32:33.423+0000] {process_utils.py:132} INFO - Sending 15 to group 2161. PIDs of all processes in the group: [2161]
[2024-07-11T00:32:33.424+0000] {process_utils.py:87} INFO - Sending the signal 15 to group 2161
[2024-07-11T00:32:34.632+0000] {taskinstance.py:2611} ERROR - Received SIGTERM. Terminating subprocesses.
[2024-07-11T00:32:34.647+0000] {taskinstance.py:2905} ERROR - Task failed with exception
Traceback (most recent call last):
  File "/home/airflow/.local/lib/python3.12/site-packages/airflow/models/taskinstance.py", line 432, in _execute_callable
    return execute_callable(context=context, **execute_callable_kwargs)
           ^^^^^^^^^^^^^^^^^^^^^^^^^^^^^^^^^^^^^^^^^^^^^^^^^^^^^^^^^^^^
  File "/home/airflow/.local/lib/python3.12/site-packages/airflow/models/baseoperator.py", line 401, in wrapper
    return func(self, *args, **kwargs)
           ^^^^^^^^^^^^^^^^^^^^^^^^^^^
  File "/home/airflow/.local/lib/python3.12/site-packages/airflow/operators/python.py", line 235, in execute
    return_value = self.execute_callable()
                   ^^^^^^^^^^^^^^^^^^^^^^^
  File "/home/airflow/.local/lib/python3.12/site-packages/airflow/operators/python.py", line 252, in execute_callable
    return self.python_callable(*self.op_args, **self.op_kwargs)
           ^^^^^^^^^^^^^^^^^^^^^^^^^^^^^^^^^^^^^^^^^^^^^^^^^^^^^
  File "/opt/airflow/dags/fail_dags_monitor.py", line 67, in load
    conn = psycopg2.connect(database=DB_NAME,
           ^^^^^^^^^^^^^^^^^^^^^^^^^^^^^^^^^^
  File "/home/airflow/.local/lib/python3.12/site-packages/psycopg2/__init__.py", line 122, in connect
    conn = _connect(dsn, connection_factory=connection_factory, **kwasync)
           ^^^^^^^^^^^^^^^^^^^^^^^^^^^^^^^^^^^^^^^^^^^^^^^^^^^^^^^^^^^^^^^
psycopg2.OperationalError: connection to server at "athena-uat.cybjleasxg2d.ap-southeast-1.rds.amazonaws.com" (172.31.22.247), port 5432 failed: Connection refused
	Is the server running on that host and accepting TCP/IP connections?


During handling of the above exception, another exception occurred:

Traceback (most recent call last):
  File "/home/airflow/.local/lib/python3.12/site-packages/airflow/models/taskinstance.py", line 465, in _execute_task
    result = _execute_callable(context=context, **execute_callable_kwargs)
             ^^^^^^^^^^^^^^^^^^^^^^^^^^^^^^^^^^^^^^^^^^^^^^^^^^^^^^^^^^^^^
  File "/home/airflow/.local/lib/python3.12/site-packages/airflow/models/taskinstance.py", line 441, in _execute_callable
    log.info("::group::Post task execution logs")
  File "/usr/local/lib/python3.12/logging/__init__.py", line 1529, in info
    def info(self, msg, *args, **kwargs):
    
  File "/home/airflow/.local/lib/python3.12/site-packages/airflow/models/taskinstance.py", line 2613, in signal_handler
    raise AirflowTaskTerminated("Task received SIGTERM signal")
airflow.exceptions.AirflowTaskTerminated: Task received SIGTERM signal
[2024-07-11T00:32:34.653+0000] {taskinstance.py:1206} INFO - Marking task as FAILED. dag_id=Fail_Dags_Monitor, task_id=load, run_id=scheduled__2024-07-10T21:15:00+00:00, execution_date=20240710T211500, start_date=20240711T003231, end_date=20240711T003234
[2024-07-11T00:32:34.733+0000] {process_utils.py:80} INFO - Process psutil.Process(pid=2161, status='terminated', exitcode=2, started='23:22:54') (2161) terminated with exit code 2
