[2024-07-03T10:11:50.360+0000] {local_task_job_runner.py:120} INFO - ::group::Pre task execution logs
[2024-07-03T10:11:50.381+0000] {taskinstance.py:2076} INFO - Dependencies all met for dep_context=non-requeueable deps ti=<TaskInstance: Fail_Dags_Monitor.get_failed_dag manual__2024-07-03T10:11:43.875405+00:00 [queued]>
[2024-07-03T10:11:50.389+0000] {taskinstance.py:2076} INFO - Dependencies all met for dep_context=requeueable deps ti=<TaskInstance: Fail_Dags_Monitor.get_failed_dag manual__2024-07-03T10:11:43.875405+00:00 [queued]>
[2024-07-03T10:11:50.390+0000] {taskinstance.py:2306} INFO - Starting attempt 2 of 3
[2024-07-03T10:11:50.397+0000] {taskinstance.py:2330} INFO - Executing <Task(PythonOperator): get_failed_dag> on 2024-07-03 10:11:43.875405+00:00
[2024-07-03T10:11:50.406+0000] {logging_mixin.py:188} WARNING - /home/***/.local/lib/python3.12/site-packages/***/task/task_runner/standard_task_runner.py:61 DeprecationWarning: This process (pid=4883) is multi-threaded, use of fork() may lead to deadlocks in the child.
[2024-07-03T10:11:50.408+0000] {standard_task_runner.py:63} INFO - Started process 4884 to run task
[2024-07-03T10:11:50.406+0000] {standard_task_runner.py:90} INFO - Running: ['***', 'tasks', 'run', 'Fail_Dags_Monitor', 'get_failed_dag', 'manual__2024-07-03T10:11:43.875405+00:00', '--job-id', '246', '--raw', '--subdir', 'DAGS_FOLDER/fail_dags_monitor.py', '--cfg-path', '/tmp/tmpxzrkf7vq']
[2024-07-03T10:11:50.409+0000] {standard_task_runner.py:91} INFO - Job 246: Subtask get_failed_dag
[2024-07-03T10:11:50.445+0000] {task_command.py:426} INFO - Running <TaskInstance: Fail_Dags_Monitor.get_failed_dag manual__2024-07-03T10:11:43.875405+00:00 [running]> on host 0b64c9d791b9
[2024-07-03T10:11:50.542+0000] {taskinstance.py:2648} INFO - Exporting env vars: AIRFLOW_CTX_DAG_OWNER='congminh.nguyen@ponpoint.vn' AIRFLOW_CTX_DAG_ID='Fail_Dags_Monitor' AIRFLOW_CTX_TASK_ID='get_failed_dag' AIRFLOW_CTX_EXECUTION_DATE='2024-07-03T10:11:43.875405+00:00' AIRFLOW_CTX_TRY_NUMBER='2' AIRFLOW_CTX_DAG_RUN_ID='manual__2024-07-03T10:11:43.875405+00:00'
[2024-07-03T10:11:50.543+0000] {taskinstance.py:430} INFO - ::endgroup::
[2024-07-03T10:11:50.549+0000] {dagbag.py:545} INFO - Filling up the DagBag from /opt/***/dags
[2024-07-03T10:11:50.568+0000] {taskinstance.py:441} INFO - ::group::Post task execution logs
[2024-07-03T10:11:50.569+0000] {taskinstance.py:2905} ERROR - Task failed with exception
Traceback (most recent call last):
  File "/home/airflow/.local/lib/python3.12/site-packages/airflow/models/taskinstance.py", line 465, in _execute_task
    result = _execute_callable(context=context, **execute_callable_kwargs)
             ^^^^^^^^^^^^^^^^^^^^^^^^^^^^^^^^^^^^^^^^^^^^^^^^^^^^^^^^^^^^^
  File "/home/airflow/.local/lib/python3.12/site-packages/airflow/models/taskinstance.py", line 432, in _execute_callable
    return execute_callable(context=context, **execute_callable_kwargs)
           ^^^^^^^^^^^^^^^^^^^^^^^^^^^^^^^^^^^^^^^^^^^^^^^^^^^^^^^^^^^^
  File "/home/airflow/.local/lib/python3.12/site-packages/airflow/models/baseoperator.py", line 401, in wrapper
    return func(self, *args, **kwargs)
           ^^^^^^^^^^^^^^^^^^^^^^^^^^^
  File "/home/airflow/.local/lib/python3.12/site-packages/airflow/operators/python.py", line 235, in execute
    return_value = self.execute_callable()
                   ^^^^^^^^^^^^^^^^^^^^^^^
  File "/home/airflow/.local/lib/python3.12/site-packages/airflow/operators/python.py", line 252, in execute_callable
    return self.python_callable(*self.op_args, **self.op_kwargs)
           ^^^^^^^^^^^^^^^^^^^^^^^^^^^^^^^^^^^^^^^^^^^^^^^^^^^^^
  File "/opt/airflow/dags/fail_dags_monitor.py", line 39, in get_failed_dag
    'task_failed': run.task_instances,
                   ^^^^^^^^^^^^^^^^^^
  File "/home/airflow/.local/lib/python3.12/site-packages/sqlalchemy/orm/attributes.py", line 487, in __get__
    return self.impl.get(state, dict_)
           ^^^^^^^^^^^^^^^^^^^^^^^^^^^
  File "/home/airflow/.local/lib/python3.12/site-packages/sqlalchemy/orm/attributes.py", line 959, in get
    value = self._fire_loader_callables(state, key, passive)
            ^^^^^^^^^^^^^^^^^^^^^^^^^^^^^^^^^^^^^^^^^^^^^^^^
  File "/home/airflow/.local/lib/python3.12/site-packages/sqlalchemy/orm/attributes.py", line 995, in _fire_loader_callables
    return self.callable_(state, passive)
           ^^^^^^^^^^^^^^^^^^^^^^^^^^^^^^
  File "/home/airflow/.local/lib/python3.12/site-packages/sqlalchemy/orm/strategies.py", line 863, in _load_for_state
    raise orm_exc.DetachedInstanceError(
sqlalchemy.orm.exc.DetachedInstanceError: Parent instance <DagRun at 0xffffb2ab1790> is not bound to a Session; lazy load operation of attribute 'task_instances' cannot proceed (Background on this error at: https://sqlalche.me/e/14/bhk3)
[2024-07-03T10:11:50.576+0000] {taskinstance.py:1206} INFO - Marking task as UP_FOR_RETRY. dag_id=Fail_Dags_Monitor, task_id=get_failed_dag, run_id=manual__2024-07-03T10:11:43.875405+00:00, execution_date=20240703T101143, start_date=20240703T101150, end_date=20240703T101150
[2024-07-03T10:11:50.581+0000] {standard_task_runner.py:110} ERROR - Failed to execute job 246 for task get_failed_dag (Parent instance <DagRun at 0xffffb2ab1790> is not bound to a Session; lazy load operation of attribute 'task_instances' cannot proceed (Background on this error at: https://sqlalche.me/e/14/bhk3); 4884)
[2024-07-03T10:11:50.600+0000] {local_task_job_runner.py:240} INFO - Task exited with return code 1
[2024-07-03T10:11:50.610+0000] {taskinstance.py:3503} INFO - 0 downstream tasks scheduled from follow-on schedule check
[2024-07-03T10:11:50.611+0000] {local_task_job_runner.py:222} INFO - ::endgroup::
