[2024-07-04T03:10:50.612+0000] {local_task_job_runner.py:120} INFO - ::group::Pre task execution logs
[2024-07-04T03:10:50.629+0000] {taskinstance.py:2076} INFO - Dependencies all met for dep_context=non-requeueable deps ti=<TaskInstance: Fail_Dags_Monitor.get_failed_dag manual__2024-07-04T03:10:49.697287+00:00 [queued]>
[2024-07-04T03:10:50.634+0000] {taskinstance.py:2076} INFO - Dependencies all met for dep_context=requeueable deps ti=<TaskInstance: Fail_Dags_Monitor.get_failed_dag manual__2024-07-04T03:10:49.697287+00:00 [queued]>
[2024-07-04T03:10:50.634+0000] {taskinstance.py:2306} INFO - Starting attempt 1 of 3
[2024-07-04T03:10:50.641+0000] {taskinstance.py:2330} INFO - Executing <Task(PythonOperator): get_failed_dag> on 2024-07-04 03:10:49.697287+00:00
[2024-07-04T03:10:50.646+0000] {logging_mixin.py:188} WARNING - /home/***/.local/lib/python3.12/site-packages/***/task/task_runner/standard_task_runner.py:61 DeprecationWarning: This process (pid=15138) is multi-threaded, use of fork() may lead to deadlocks in the child.
[2024-07-04T03:10:50.647+0000] {standard_task_runner.py:63} INFO - Started process 15139 to run task
[2024-07-04T03:10:50.646+0000] {standard_task_runner.py:90} INFO - Running: ['***', 'tasks', 'run', 'Fail_Dags_Monitor', 'get_failed_dag', 'manual__2024-07-04T03:10:49.697287+00:00', '--job-id', '318', '--raw', '--subdir', 'DAGS_FOLDER/fail_dags_monitor.py', '--cfg-path', '/tmp/tmpnr9saspw']
[2024-07-04T03:10:50.647+0000] {standard_task_runner.py:91} INFO - Job 318: Subtask get_failed_dag
[2024-07-04T03:10:50.674+0000] {task_command.py:426} INFO - Running <TaskInstance: Fail_Dags_Monitor.get_failed_dag manual__2024-07-04T03:10:49.697287+00:00 [running]> on host 0b64c9d791b9
[2024-07-04T03:10:50.723+0000] {taskinstance.py:2648} INFO - Exporting env vars: AIRFLOW_CTX_DAG_OWNER='congminh.nguyen@ponpoint.vn' AIRFLOW_CTX_DAG_ID='Fail_Dags_Monitor' AIRFLOW_CTX_TASK_ID='get_failed_dag' AIRFLOW_CTX_EXECUTION_DATE='2024-07-04T03:10:49.697287+00:00' AIRFLOW_CTX_TRY_NUMBER='1' AIRFLOW_CTX_DAG_RUN_ID='manual__2024-07-04T03:10:49.697287+00:00'
[2024-07-04T03:10:50.724+0000] {taskinstance.py:430} INFO - ::endgroup::
[2024-07-04T03:10:50.733+0000] {dagbag.py:545} INFO - Filling up the DagBag from /opt/***/dags
[2024-07-04T03:10:50.753+0000] {taskinstance.py:441} INFO - ::group::Post task execution logs
[2024-07-04T03:10:50.754+0000] {taskinstance.py:2905} ERROR - Task failed with exception
Traceback (most recent call last):
  File "/home/airflow/.local/lib/python3.12/site-packages/airflow/models/taskinstance.py", line 465, in _execute_task
    result = _execute_callable(context=context, **execute_callable_kwargs)
             ^^^^^^^^^^^^^^^^^^^^^^^^^^^^^^^^^^^^^^^^^^^^^^^^^^^^^^^^^^^^^
  File "/home/airflow/.local/lib/python3.12/site-packages/airflow/models/taskinstance.py", line 432, in _execute_callable
    return execute_callable(context=context, **execute_callable_kwargs)
           ^^^^^^^^^^^^^^^^^^^^^^^^^^^^^^^^^^^^^^^^^^^^^^^^^^^^^^^^^^^^
  File "/home/airflow/.local/lib/python3.12/site-packages/airflow/models/baseoperator.py", line 401, in wrapper
    return func(self, *args, **kwargs)
           ^^^^^^^^^^^^^^^^^^^^^^^^^^^
  File "/home/airflow/.local/lib/python3.12/site-packages/airflow/operators/python.py", line 235, in execute
    return_value = self.execute_callable()
                   ^^^^^^^^^^^^^^^^^^^^^^^
  File "/home/airflow/.local/lib/python3.12/site-packages/airflow/operators/python.py", line 252, in execute_callable
    return self.python_callable(*self.op_args, **self.op_kwargs)
           ^^^^^^^^^^^^^^^^^^^^^^^^^^^^^^^^^^^^^^^^^^^^^^^^^^^^^
  File "/opt/airflow/dags/fail_dags_monitor.py", line 40, in get_failed_dag
    'owner': map_dict['dag_owner'],
             ~~~~~~~~^^^^^^^^^^^^^
KeyError: 'dag_owner'
[2024-07-04T03:10:50.759+0000] {taskinstance.py:1206} INFO - Marking task as UP_FOR_RETRY. dag_id=Fail_Dags_Monitor, task_id=get_failed_dag, run_id=manual__2024-07-04T03:10:49.697287+00:00, execution_date=20240704T031049, start_date=20240704T031050, end_date=20240704T031050
[2024-07-04T03:10:50.765+0000] {standard_task_runner.py:110} ERROR - Failed to execute job 318 for task get_failed_dag ('dag_owner'; 15139)
[2024-07-04T03:10:50.788+0000] {local_task_job_runner.py:240} INFO - Task exited with return code 1
[2024-07-04T03:10:50.803+0000] {taskinstance.py:3503} INFO - 0 downstream tasks scheduled from follow-on schedule check
[2024-07-04T03:10:50.804+0000] {local_task_job_runner.py:222} INFO - ::endgroup::
