[2024-07-04T03:11:56.151+0000] {local_task_job_runner.py:120} INFO - ::group::Pre task execution logs
[2024-07-04T03:11:56.170+0000] {taskinstance.py:2076} INFO - Dependencies all met for dep_context=non-requeueable deps ti=<TaskInstance: Fail_Dags_Monitor.get_failed_dag manual__2024-07-04T03:10:49.697287+00:00 [queued]>
[2024-07-04T03:11:56.175+0000] {taskinstance.py:2076} INFO - Dependencies all met for dep_context=requeueable deps ti=<TaskInstance: Fail_Dags_Monitor.get_failed_dag manual__2024-07-04T03:10:49.697287+00:00 [queued]>
[2024-07-04T03:11:56.175+0000] {taskinstance.py:2306} INFO - Starting attempt 5 of 6
[2024-07-04T03:11:56.181+0000] {taskinstance.py:2330} INFO - Executing <Task(PythonOperator): get_failed_dag> on 2024-07-04 03:10:49.697287+00:00
[2024-07-04T03:11:56.186+0000] {logging_mixin.py:188} WARNING - /home/***/.local/lib/python3.12/site-packages/***/task/task_runner/standard_task_runner.py:61 DeprecationWarning: This process (pid=15193) is multi-threaded, use of fork() may lead to deadlocks in the child.
[2024-07-04T03:11:56.187+0000] {standard_task_runner.py:63} INFO - Started process 15194 to run task
[2024-07-04T03:11:56.186+0000] {standard_task_runner.py:90} INFO - Running: ['***', 'tasks', 'run', 'Fail_Dags_Monitor', 'get_failed_dag', 'manual__2024-07-04T03:10:49.697287+00:00', '--job-id', '324', '--raw', '--subdir', 'DAGS_FOLDER/fail_dags_monitor.py', '--cfg-path', '/tmp/tmphwvcbgab']
[2024-07-04T03:11:56.187+0000] {standard_task_runner.py:91} INFO - Job 324: Subtask get_failed_dag
[2024-07-04T03:11:56.215+0000] {task_command.py:426} INFO - Running <TaskInstance: Fail_Dags_Monitor.get_failed_dag manual__2024-07-04T03:10:49.697287+00:00 [running]> on host 0b64c9d791b9
[2024-07-04T03:11:56.268+0000] {taskinstance.py:2648} INFO - Exporting env vars: AIRFLOW_CTX_DAG_OWNER='congminh.nguyen@ponpoint.vn' AIRFLOW_CTX_DAG_ID='Fail_Dags_Monitor' AIRFLOW_CTX_TASK_ID='get_failed_dag' AIRFLOW_CTX_EXECUTION_DATE='2024-07-04T03:10:49.697287+00:00' AIRFLOW_CTX_TRY_NUMBER='5' AIRFLOW_CTX_DAG_RUN_ID='manual__2024-07-04T03:10:49.697287+00:00'
[2024-07-04T03:11:56.269+0000] {taskinstance.py:430} INFO - ::endgroup::
[2024-07-04T03:11:56.276+0000] {dagbag.py:545} INFO - Filling up the DagBag from /opt/***/dags
[2024-07-04T03:11:56.296+0000] {taskinstance.py:441} INFO - ::group::Post task execution logs
[2024-07-04T03:11:56.297+0000] {taskinstance.py:2905} ERROR - Task failed with exception
Traceback (most recent call last):
  File "/home/airflow/.local/lib/python3.12/site-packages/airflow/models/taskinstance.py", line 465, in _execute_task
    result = _execute_callable(context=context, **execute_callable_kwargs)
             ^^^^^^^^^^^^^^^^^^^^^^^^^^^^^^^^^^^^^^^^^^^^^^^^^^^^^^^^^^^^^
  File "/home/airflow/.local/lib/python3.12/site-packages/airflow/models/taskinstance.py", line 432, in _execute_callable
    return execute_callable(context=context, **execute_callable_kwargs)
           ^^^^^^^^^^^^^^^^^^^^^^^^^^^^^^^^^^^^^^^^^^^^^^^^^^^^^^^^^^^^
  File "/home/airflow/.local/lib/python3.12/site-packages/airflow/models/baseoperator.py", line 401, in wrapper
    return func(self, *args, **kwargs)
           ^^^^^^^^^^^^^^^^^^^^^^^^^^^
  File "/home/airflow/.local/lib/python3.12/site-packages/airflow/operators/python.py", line 235, in execute
    return_value = self.execute_callable()
                   ^^^^^^^^^^^^^^^^^^^^^^^
  File "/home/airflow/.local/lib/python3.12/site-packages/airflow/operators/python.py", line 252, in execute_callable
    return self.python_callable(*self.op_args, **self.op_kwargs)
           ^^^^^^^^^^^^^^^^^^^^^^^^^^^^^^^^^^^^^^^^^^^^^^^^^^^^^
  File "/opt/airflow/dags/fail_dags_monitor.py", line 40, in get_failed_dag
    'owner': map_dict['dag_owner'],
             ~~~~~~~~^^^^^^^^^^^^^
KeyError: 'dag_owner'
[2024-07-04T03:11:56.302+0000] {taskinstance.py:1206} INFO - Marking task as UP_FOR_RETRY. dag_id=Fail_Dags_Monitor, task_id=get_failed_dag, run_id=manual__2024-07-04T03:10:49.697287+00:00, execution_date=20240704T031049, start_date=20240704T031156, end_date=20240704T031156
[2024-07-04T03:11:56.307+0000] {standard_task_runner.py:110} ERROR - Failed to execute job 324 for task get_failed_dag ('dag_owner'; 15194)
[2024-07-04T03:11:56.328+0000] {local_task_job_runner.py:240} INFO - Task exited with return code 1
[2024-07-04T03:11:56.342+0000] {taskinstance.py:3503} INFO - 0 downstream tasks scheduled from follow-on schedule check
[2024-07-04T03:11:56.343+0000] {local_task_job_runner.py:222} INFO - ::endgroup::
